[0;31mTypeError: test/samples/compiler/function_call_bad_kwd_arg.py:5:3
[0m[0mcallable `fn` was given an unexpected keyword argument `c`[0m
[0m  5| fn(c=4)
[0m
exitcode=1